Workbook

Sheet Overview
A1: GULF OIL LUBRICANTS INDIA (NSE: GULFOILLUB) — LEVERAGED BUYOUT ANALYSIS
A2: Hypothetical take-private by a financial sponsor | Market data 22-Sep-2026; financials through Q1 FY2027 (June 2026) | Rs crore
A4: Why Gulf Oil Lubricants as an LBO candidate
A5: Hinduja-group lubricant marketer with sticky B2C, OEM and industrial demand, ~12-13% EBITDA margins, capex of only ~1.3% of revenue, a negative working-capital cycle, a net-cash balance sheet (Rs ~1,150 cr cash vs Rs ~514 cr borrowings) and a 5% dividend yield - the kind of cash-generative, asset-light business sponsors like. The promoter (Gulf Oil International (Mauritius)) holds 67%, so a buyout is conceivable. The catch, which this model tests, is price: the listed valuation is already ~10-12x EBITDA, and Indian acquisition debt is scarce and expensive.
A7: How to read this workbook
A8: Assumptions - all inputs in one place, including a 3-way operating scenario switch (Downside / Base / Upside) in cell B40.
A9: LBO Model - projections, free cash flow, senior loan + NCD schedule with cash sweep, and credit statistics.
A10: Transaction - sources & uses (including use of existing balance-sheet cash) and headline deal metrics.
A11: Returns - exit waterfall, IRR / MOIC by exit year, two sensitivity tables, and an ability-to-pay analysis at the hurdle IRR.
A13: Indian structuring & regulatory points (discussed, NOT modelled)
A14: 1) RBI rules restrict banks from lending against shares for acquisitions, so acquisition debt would have to come from NBFCs, AIFs/private credit, NCDs or foreign lenders (ECB rules) - hence the modest 3.5x leverage and 10.5-12.5% rates. 2) Section 67 of the Companies Act restricts a target financing the purchase of its own shares, so the usual route is an acquisition SPV that later merges with the target (needs NCLT approval); the 'use of existing cash' source here is therefore a simplification. 3) A 100% take-private of a listed company needs SEBI open-offer and delisting (reverse book-building) compliance and promoter cooperation - the 30% premium is only a placeholder for the discovered price.
A16: Headline outputs (live - update with the scenario switch)
A17: Scenario | B17: =Assumptions!$B$41 -> Base
A18: Offer price per share (Rs) | B18: =Assumptions!$B$7 -> 1368.25
A19: Enterprise value (Rs crore) | B19: =Assumptions!$B$12 -> 6121.055
A20: EV / FY2027E Adj. EBITDA | B20: =Assumptions!$B$16 -> 10.414913
A21: Total leverage at close | B21: =Assumptions!$B$28 -> 3.5
A22: Sponsor equity cheque (Rs crore) | B22: =Transaction!$B$8 -> 4496.9906
A23: Sponsor equity % of total sources | B23: =Transaction!C8 -> 0.60716718
A24: 5-year MOIC | B24: =Returns!D13 -> 1.9196641
A25: 5-year IRR (INR) | B25: =Returns!D14 -> 0.13931823
A26: Maximum offer price for hurdle IRR (Rs per share) | B26: =Returns!B41 -> 1163.2885
A27: Total debt / EBITDA at exit (FY2032E) | B27: ='LBO Model'!H42 -> 0.73258481
A29: Disclaimer: academic / portfolio exercise. No transaction involving Gulf Oil Lubricants India has been announced; the premium, financing terms and projections are the author's hypothetical assumptions built on public information, not investment advice.

Sheet Assumptions
A1: GULF OIL LUBRICANTS INDIA (NSE: GULFOILLUB) — LBO ASSUMPTIONS
A2: Rs crore unless stated | Hypothetical take-private by a financial sponsor | Blue = input, black = formula, green = cross-sheet link
A4: Transaction
A5: Current share price (Rs) — NSE close 22-Sep-2026 | B5: 1052.5
A6: Offer premium to current price | B6: 0.3
A7: Offer price per share (Rs) | B7: =B5*(1+B6) -> 1368.25
A8: Shares outstanding (crore) | B8: 4.94
A9: Equity purchase price (100% of shares) | B9: =B7*B8 -> 6759.155
A10: (+) Existing borrowings refinanced (Mar-2026) | B10: 514.4
A11: (-) Existing cash & short-term investments (Mar-2026) | B11: 1152.5
A12: Enterprise value (EV) | B12: =B9+B10-B11 -> 6121.055
A13: FY2026A consolidated Adj. EBITDA (reported) | B13: 513.89
A14: FY2027E Adj. EBITDA (entry basis) | B14: ='LBO Model'!C7 -> 587.7202
A15: EV / FY2026A EBITDA | B15: =B12/B13 -> 11.911216
A16: EV / FY2027E EBITDA | B16: =B12/B14 -> 10.414913
A18: Entry-year (FY2027E) estimates — common to all scenarios
A19: FY2027E revenue growth | B19: 0.15
A20: FY2027E Adj. EBITDA margin | B20: 0.126
A22: Financing
A23: Senior secured term loan (x FY2027E EBITDA) | B23: 2.5
A24: Subordinated NCDs (x FY2027E EBITDA) | B24: 1
A25: Senior term loan amount | B25: =B23*B14 -> 1469.3005
A26: NCD amount | B26: =B24*B14 -> 587.7202
A27: Total new debt | B27: =B25+B26 -> 2057.0207
A28: Total leverage at close (x FY2027E EBITDA) | B28: =B27/B14 -> 3.5
A29: Senior term loan interest rate | B29: 0.105
A30: NCD interest rate | B30: 0.125
A31: Senior loan mandatory amortisation (% of original, p.a.) | B31: 0.05
A32: Cash sweep (% of excess cash used to prepay senior loan) | B32: 1
A33: Financing fees (% of new debt) | B33: 0.02
A34: Advisory, stamp duty & other costs (% of EV) | B34: 0.015
A35: Minimum cash retained in the business | B35: 300
A36: Existing cash used as a source of funds | B36: =MAX(0,B11-B35) -> 852.5
A37: Cash tax rate (new regime, incl. surcharge & cess) | B37: 0.2517
A39: Operating scenario (FY2028E-FY2032E)
A40: Scenario selector (1 = Downside, 2 = Base, 3 = Upside) | B40: 2
A41: Live scenario | B41: =CHOOSE(B40,"Downside","Base","Upside") -> Base
D43: FY2028E | E43: FY2029E | F43: FY2030E | G43: FY2031E | H43: FY2032E
A44: Revenue growth - Downside | D44: 0.05 | E44: 0.04 | F44: 0.04 | G44: 0.04 | H44: 0.04
A45: Revenue growth - Base | D45: 0.09 | E45: 0.09 | F45: 0.08 | G45: 0.08 | H45: 0.07
...

Sheet Transaction
A1: TRANSACTION — SOURCES & USES
A2: Rs crore
A4: Sources | B4: Rs crore | C4: % of total | D4: x FY27E EBITDA
A5: Senior secured term loan | B5: =Assumptions!$B$25 -> 1469.3005 | C5: =B5/$B$9 -> 0.19837957 | D5: =B5/Assumptions!$B$14 -> 2.5
A6: Subordinated NCDs | B6: =Assumptions!$B$26 -> 587.7202 | C6: =B6/$B$9 -> 0.079351827 | D6: =B6/Assumptions!$B$14 -> 1
A7: Existing balance-sheet cash used | B7: =Assumptions!$B$36 -> 852.5 | C7: =B7/$B$9 -> 0.11510143 | D7: =B7/Assumptions!$B$14 -> 1.4505202
A8: Sponsor equity (plug) | B8: =B16-B5-B6-B7 -> 4496.9906 | C8: =B8/$B$9 -> 0.60716718 | D8: =B8/Assumptions!$B$14 -> 7.6515842
A9: Total sources | B9: =SUM(B5:B8) -> 7406.5112 | C9: =B9/$B$9 -> 1 | D9: =B9/Assumptions!$B$14 -> 12.602104
A11: Uses | B11: Rs crore | C11: % of total | D11: x FY27E EBITDA
A12: Purchase of 100% equity | B12: =Assumptions!$B$9 -> 6759.155 | C12: =B12/$B$16 -> 0.91259633 | D12: =B12/Assumptions!$B$14 -> 11.500634
A13: Refinance existing borrowings | B13: =Assumptions!$B$10 -> 514.4 | C13: =B13/$B$16 -> 0.069452403 | D13: =B13/Assumptions!$B$14 -> 0.87524642
A14: Financing fees | B14: =Assumptions!$B$33*Assumptions!$B$27 -> 41.140414 | C14: =B14/$B$16 -> 0.0055546279 | D14: =B14/Assumptions!$B$14 -> 0.07
A15: Advisory, stamp duty & other costs | B15: =Assumptions!$B$34*Assumptions!$B$12 -> 91.815825 | C15: =B15/$B$16 -> 0.012396636 | D15: =B15/Assumptions!$B$14 -> 0.1562237
A16: Total uses | B16: =SUM(B12:B15) -> 7406.5112 | C16: =B16/$B$16 -> 1 | D16: =B16/Assumptions!$B$14 -> 12.602104
A18: Check: sources - uses (should be zero) | B18: =B9-B16 -> 0
A20: Deal Metrics
A21: Offer price per share (Rs) | B21: =Assumptions!$B$7 -> 1368.25
A22: Premium to current price | B22: =Assumptions!$B$6 -> 0.3
A23: Enterprise value (Rs crore) | B23: =Assumptions!$B$12 -> 6121.055
A24: EV / FY2026A Adj. EBITDA | B24: =Assumptions!$B$15 -> 11.911216
A25: EV / FY2027E Adj. EBITDA | B25: =Assumptions!$B$16 -> 10.414913
A26: Total leverage at close | B26: =Assumptions!$B$28 -> 3.5
A27: Sponsor equity contribution (% of total sources) | B27: =C8 -> 0.60716718

Sheet LBO Model
A1: LBO MODEL — OPERATING PROJECTIONS, CASH FLOW & DEBT SCHEDULE
A2: Rs crore | Fiscal year ends 31 March | Close assumed at end of FY2027E; projection years FY2028E-FY2032E
B4: FY2026A | C4: FY2027E (Close) | D4: FY2028E | E4: FY2029E | F4: FY2030E | G4: FY2031E | H4: FY2032E
A5: Revenue | B5: 4056.04 | C5: =B5*(1+Assumptions!$B$19) -> 4664.446 | D5: =C5*(1+Assumptions!D47) -> 5084.2461 | E5: =D5*(1+Assumptions!E47) -> 5541.8283 | F5: =E5*(1+Assumptions!F47) -> 5985.1746 | G5: =F5*(1+Assumptions!G47) -> 6463.9885 | H5: =G5*(1+Assumptions!H47) -> 6916.4677
A6: % growth | C6: =C5/B5-1 -> 0.15 | D6: =D5/C5-1 -> 0.09 | E6: =E5/D5-1 -> 0.09 | F6: =F5/E5-1 -> 0.08 | G6: =G5/F5-1 -> 0.08 | H6: =H5/G5-1 -> 0.07
A7: Adj. EBITDA (as reported, post-Ind AS 116) | B7: =Assumptions!$B$13 -> 513.89 | C7: =C5*Assumptions!$B$20 -> 587.7202 | D7: =D5*Assumptions!D52 -> 640.61501 | E7: =E5*Assumptions!E52 -> 703.81219 | F7: =F5*Assumptions!F52 -> 766.10234 | G7: =G5*Assumptions!G52 -> 833.85452 | H7: =H5*Assumptions!H52 -> 899.1408
A8: % margin | B8: =B7/B5 -> 0.12669747 | C8: =C7/C5 -> 0.126 | D8: =D7/D5 -> 0.126 | E8: =E7/E5 -> 0.127 | F8: =F7/F5 -> 0.128 | G8: =G7/G5 -> 0.129 | H8: =H7/H5 -> 0.13
A9: (-) Lease payments (Ind AS 116) | D9: =D5*Assumptions!D58 -> 61.010954 | E9: =E5*Assumptions!E58 -> 66.50194 | F9: =F5*Assumptions!F58 -> 71.822095 | G9: =G5*Assumptions!G58 -> 77.567862 | H9: =H5*Assumptions!H58 -> 82.997613
A10: EBITDA after lease payments | D10: =D7-D9 -> 579.60406 | E10: =E7-E9 -> 637.31025 | F10: =F7-F9 -> 694.28025 | G10: =G7-G9 -> 756.28666 | H10: =H7-H9 -> 816.14319
A11: (-) Depreciation & amortisation | D11: =D5*Assumptions!D54 -> 61.010954 | E11: =E5*Assumptions!E54 -> 66.50194 | F11: =F5*Assumptions!F54 -> 71.822095 | G11: =G5*Assumptions!G54 -> 77.567862 | H11: =H5*Assumptions!H54 -> 82.997613
A12: (-) Integration & other one-off cash costs | D12: =Assumptions!D57 -> 15 | E12: =Assumptions!E57 -> 10 | F12: =Assumptions!F57 -> 0 | G12: =Assumptions!G57 -> 0 | H12: =Assumptions!H57 -> 0
A13: EBIT | D13: =D10-D11-D12 -> 503.59311 | E13: =E10-E11-E12 -> 560.80831 | F13: =F10-F11-F12 -> 622.45815 | G13: =G10-G11-G12 -> 678.71879 | H13: =H10-H11-H12 -> 733.14558
A14: (-) Interest - senior term loan | D14: =D32*Assumptions!$B$29 -> 154.27655 | E14: =E32*Assumptions!$B$29 -> 137.1965 | F14: =F32*Assumptions!$B$29 -> 114.69241 | G14: =G32*Assumptions!$B$29 -> 85.549747 | H14: =H32*Assumptions!$B$29 -> 50.095298
A15: (-) Interest - NCDs | D15: =C36*Assumptions!$B$30 -> 73.465024 | E15: =D36*Assumptions!$B$30 -> 73.465024 | F15: =E36*Assumptions!$B$30 -> 73.465024 | G15: =F36*Assumptions!$B$30 -> 73.465024 | H15: =G36*Assumptions!$B$30 -> 73.465024
A16: Total interest expense | D16: =D14+D15 -> 227.74158 | E16: =E14+E15 -> 210.66152 | F16: =F14+F15 -> 188.15744 | G16: =G14+G15 -> 159.01477 | H16: =H14+H15 -> 123.56032
A17: Profit before tax | D17: =D13-D16 -> 275.85153 | E17: =E13-E16 -> 350.14679 | F17: =F13-F16 -> 434.30072 | G17: =G13-G16 -> 519.70402 | H17: =H13-H16 -> 609.58526
A18: (-) Cash taxes | D18: =MAX(0,D17)*Assumptions!$B$37 -> 69.43183 | E18: =MAX(0,E17)*Assumptions!$B$37 -> 88.131948 | F18: =MAX(0,F17)*Assumptions!$B$37 -> 109.31349 | G18: =MAX(0,G17)*Assumptions!$B$37 -> 130.8095 | H18: =MAX(0,H17)*Assumptions!$B$37 -> 153.43261
A19: Net income | D19: =D17-D18 -> 206.4197 | E19: =E17-E18 -> 262.01485 | F19: =F17-F18 -> 324.98723 | G19: =G17-G18 -> 388.89452 | H19: =H17-H18 -> 456.15265
A21: Cash Flow
A22: Net income | D22: =D19 -> 206.4197 | E22: =E19 -> 262.01485 | F22: =F19 -> 324.98723 | G22: =G19 -> 388.89452 | H22: =H19 -> 456.15265
A23: (+) Depreciation & amortisation | D23: =D11 -> 61.010954 | E23: =E11 -> 66.50194 | F23: =F11 -> 71.822095 | G23: =G11 -> 77.567862 | H23: =H11 -> 82.997613
A24: (-) Capital expenditure | D24: =-D5*Assumptions!D55 -> -71.179446 | E24: =-E5*Assumptions!E55 -> -77.585596 | F24: =-F5*Assumptions!F55 -> -83.792444 | G24: =-G5*Assumptions!G55 -> -90.495839 | H24: =-H5*Assumptions!H55 -> -96.830548
A25: (-) Investment in net working capital | D25: =-(D5-C5)*Assumptions!D56 -> -33.584011 | E25: =-(E5-D5)*Assumptions!E56 -> -36.606572 | F25: =-(F5-E5)*Assumptions!F56 -> -35.467701 | G25: =-(G5-F5)*Assumptions!G56 -> -38.305117 | H25: =-(H5-G5)*Assumptions!H56 -> -36.198336
A26: Free cash flow before debt repayment | D26: =SUM(D22:D25) -> 162.6672 | E26: =SUM(E22:E25) -> 214.32462 | F26: =SUM(F22:F25) -> 277.54918 | G26: =SUM(G22:G25) -> 337.66143 | H26: =SUM(H22:H25) -> 406.12138
A27: Net change in cash (after debt repayment) | D27: =D26+D33+D34 -> 0 | E27: =E26+E33+E34 -> 0 | F27: =F26+F33+F34 -> 0 | G27: =G26+G33+G34 -> 0 | H27: =H26+H33+H34 -> 0
A28: Cash available for optional prepayment | D28: =MAX(0,C38+D26+D33-Assumptions!$B$35) -> 89.202172 | E28: =MAX(0,D38+E26+E33-Assumptions!$B$35) -> 140.85959 | F28: =MAX(0,E38+F26+F33-Assumptions!$B$35) -> 204.08415 | G28: =MAX(0,F38+G26+G33-Assumptions!$B$35) -> 264.1964 | H28: =MAX(0,G38+H26+H33-Assumptions!$B$35) -> 332.65635
A29: FCF conversion (FCF / Adj. EBITDA) | D29: =D26/D7 -> 0.25392348 | E29: =E26/E7 -> 0.30451961 | F29: =F26/F7 -> 0.36228734 | G29: =G26/G7 -> 0.40494045 | H29: =H26/H7 -> 0.45167717
A31: Debt Schedule
A32: Senior term loan - beginning | D32: =C35 -> 1469.3005 | E32: =D35 -> 1306.6333 | F32: =E35 -> 1092.3087 | G32: =F35 -> 814.7595 | H32: =G35 -> 477.09807
A33: (-) Mandatory amortisation | D33: =-MIN(D32,Assumptions!$B$31*Assumptions!$B$25) -> -73.465024 | E33: =-MIN(E32,Assumptions!$B$31*Assumptions!$B$25) -> -73.465024 | F33: =-MIN(F32,Assumptions!$B$31*Assumptions!$B$25) -> -73.465024 | G33: =-MIN(G32,Assumptions!$B$31*Assumptions!$B$25) -> -73.465024 | H33: =-MIN(H32,Assumptions!$B$31*Assumptions!$B$25) -> -73.465024
A34: (-) Optional prepayment (cash sweep) | D34: =-MIN(D32+D33,Assumptions!$B$32*D28) -> -89.202172 | E34: =-MIN(E32+E33,Assumptions!$B$32*E28) -> -140.85959 | F34: =-MIN(F32+F33,Assumptions!$B$32*F28) -> -204.08415 | G34: =-MIN(G32+G33,Assumptions!$B$32*G28) -> -264.1964 | H34: =-MIN(H32+H33,Assumptions!$B$32*H28) -> -332.65635
A35: Senior term loan - ending | C35: =Assumptions!$B$25 -> 1469.3005 | D35: =D32+D33+D34 -> 1306.6333 | E35: =E32+E33+E34 -> 1092.3087 | F35: =F32+F33+F34 -> 814.7595 | G35: =G32+G33+G34 -> 477.09807 | H35: =H32+H33+H34 -> 70.976697
A36: Subordinated NCDs - ending (bullet) | C36: =Assumptions!$B$26 -> 587.7202 | D36: =C36 -> 587.7202 | E36: =D36 -> 587.7202 | F36: =E36 -> 587.7202 | G36: =F36 -> 587.7202 | H36: =G36 -> 587.7202
A37: Total debt | C37: =C35+C36 -> 2057.0207 | D37: =D35+D36 -> 1894.3535 | E37: =E35+E36 -> 1680.0289 | F37: =F35+F36 -> 1402.4797 | G37: =G35+G36 -> 1064.8183 | H37: =H35+H36 -> 658.69689
A38: Cash - ending | C38: =Assumptions!$B$11-Assumptions!$B$36 -> 300 | D38: =C38+D27 -> 300 | E38: =D38+E27 -> 300 | F38: =E38+F27 -> 300 | G38: =F38+G27 -> 300 | H38: =G38+H27 -> 300
A39: Net debt | C39: =C37-C38 -> 1757.0207 | D39: =D37-D38 -> 1594.3535 | E39: =E37-E38 -> 1380.0289 | F39: =F37-F38 -> 1102.4797 | G39: =G37-G38 -> 764.81827 | H39: =H37-H38 -> 358.69689
A41: Credit Statistics
A42: Total debt / Adj. EBITDA | C42: =C37/C7 -> 3.5 | D42: =D37/D7 -> 2.9570857 | E42: =E37/E7 -> 2.3870414 | F42: =F37/F7 -> 1.8306688 | G42: =G37/G7 -> 1.2769833 | H42: =H37/H7 -> 0.73258481
A43: Net debt / Adj. EBITDA | C43: =C39/C7 -> 2.989553 | D43: =D39/D7 -> 2.4887857 | E43: =E39/E7 -> 1.9607914 | F43: =F39/F7 -> 1.4390763 | G43: =G39/G7 -> 0.91720828 | H43: =H39/H7 -> 0.39893295
A44: Adj. EBITDA / interest expense | D44: =D7/D16 -> 2.8129032 | E44: =E7/E16 -> 3.3409623 | F44: =F7/F16 -> 4.0716028 | G44: =G7/G16 -> 5.2438809 | H44: =H7/H16 -> 7.276938
...

Sheet Returns
A1: RETURNS ANALYSIS
A2: Rs crore | Returns to the sponsor in INR; no interim dividends assumed; exit at end of the stated year
A4: Exit year | B4: FY2030E | C4: FY2031E | D4: FY2032E
A5: Years held | B5: 3 | C5: 4 | D5: 5
A6: Exit-year Adj. EBITDA | B6: =INDEX('LBO Model'!$D$7:$H$7,B5) -> 766.10234 | C6: =INDEX('LBO Model'!$D$7:$H$7,C5) -> 833.85452 | D6: =INDEX('LBO Model'!$D$7:$H$7,D5) -> 899.1408
A7: Exit multiple | B7: =Assumptions!$B$61 -> 10 | C7: =Assumptions!$B$61 -> 10 | D7: =Assumptions!$B$61 -> 10
A8: Exit enterprise value | B8: =B6*B7 -> 7661.0234 | C8: =C6*C7 -> 8338.5452 | D8: =D6*D7 -> 8991.408
A9: (-) Total debt at exit | B9: =-INDEX('LBO Model'!$D$37:$H$37,B5) -> -1402.4797 | C9: =-INDEX('LBO Model'!$D$37:$H$37,C5) -> -1064.8183 | D9: =-INDEX('LBO Model'!$D$37:$H$37,D5) -> -658.69689
A10: (+) Cash at exit | B10: =INDEX('LBO Model'!$D$38:$H$38,B5) -> 300 | C10: =INDEX('LBO Model'!$D$38:$H$38,C5) -> 300 | D10: =INDEX('LBO Model'!$D$38:$H$38,D5) -> 300
A11: Exit equity value | B11: =SUM(B8:B10) -> 6558.5437 | C11: =SUM(C8:C10) -> 7573.7269 | D11: =SUM(D8:D10) -> 8632.7111
A12: Sponsor equity invested | B12: =Transaction!$B$8 -> 4496.9906 | C12: =Transaction!$B$8 -> 4496.9906 | D12: =Transaction!$B$8 -> 4496.9906
A13: MOIC | B13: =B11/B12 -> 1.4584295 | C13: =C11/C12 -> 1.6841767 | D13: =D11/D12 -> 1.9196641
A14: IRR (INR) | B14: =B13^(1/B5)-1 -> 0.13404028 | C14: =C13^(1/C5)-1 -> 0.13919197 | D14: =D13^(1/D5)-1 -> 0.13931823
A16: Sensitivity 1: IRR vs. exit multiple and exit year
A17: Exit multiple (x) \ Years held | B17: 3 | C17: 4 | D17: 5
A18: 8 | B18: =(($A18*INDEX('LBO Model'!$D$7:$H$7,B$17)-INDEX('LBO Model'!$D$37:$H$37,B$17)+INDEX('LBO Model'!$D$38:$H$38,B$17))/Transaction!$B$8)^(1/B$17)-1 -> 0.037791084 | C18: =(($A18*INDEX('LBO Model'!$D$7:$H$7,C$17)-INDEX('LBO Model'!$D$37:$H$37,C$17)+INDEX('LBO Model'!$D$38:$H$38,C$17))/Transaction!$B$8)^(1/C$17)-1 -> 0.070516081 | D18: =(($A18*INDEX('LBO Model'!$D$7:$H$7,D$17)-INDEX('LBO Model'!$D$37:$H$37,D$17)+INDEX('LBO Model'!$D$38:$H$38,D$17))/Transaction!$B$8)^(1/D$17)-1 -> 0.087316701
A19: 8.5 | B19: =(($A19*INDEX('LBO Model'!$D$7:$H$7,B$17)-INDEX('LBO Model'!$D$37:$H$37,B$17)+INDEX('LBO Model'!$D$38:$H$38,B$17))/Transaction!$B$8)^(1/B$17)-1 -> 0.063511308 | C19: =(($A19*INDEX('LBO Model'!$D$7:$H$7,C$17)-INDEX('LBO Model'!$D$37:$H$37,C$17)+INDEX('LBO Model'!$D$38:$H$38,C$17))/Transaction!$B$8)^(1/C$17)-1 -> 0.088928488 | D19: =(($A19*INDEX('LBO Model'!$D$7:$H$7,D$17)-INDEX('LBO Model'!$D$37:$H$37,D$17)+INDEX('LBO Model'!$D$38:$H$38,D$17))/Transaction!$B$8)^(1/D$17)-1 -> 0.10125931
A20: 9 | B20: =(($A20*INDEX('LBO Model'!$D$7:$H$7,B$17)-INDEX('LBO Model'!$D$37:$H$37,B$17)+INDEX('LBO Model'!$D$38:$H$38,B$17))/Transaction!$B$8)^(1/B$17)-1 -> 0.088044249 | C20: =(($A20*INDEX('LBO Model'!$D$7:$H$7,C$17)-INDEX('LBO Model'!$D$37:$H$37,C$17)+INDEX('LBO Model'!$D$38:$H$38,C$17))/Transaction!$B$8)^(1/C$17)-1 -> 0.10645161 | D20: =(($A20*INDEX('LBO Model'!$D$7:$H$7,D$17)-INDEX('LBO Model'!$D$37:$H$37,D$17)+INDEX('LBO Model'!$D$38:$H$38,D$17))/Transaction!$B$8)^(1/D$17)-1 -> 0.11452961
A21: 9.5 | B21: =(($A21*INDEX('LBO Model'!$D$7:$H$7,B$17)-INDEX('LBO Model'!$D$37:$H$37,B$17)+INDEX('LBO Model'!$D$38:$H$38,B$17))/Transaction!$B$8)^(1/B$17)-1 -> 0.11151811 | C21: =(($A21*INDEX('LBO Model'!$D$7:$H$7,C$17)-INDEX('LBO Model'!$D$37:$H$37,C$17)+INDEX('LBO Model'!$D$38:$H$38,C$17))/Transaction!$B$8)^(1/C$17)-1 -> 0.12317964 | D21: =(($A21*INDEX('LBO Model'!$D$7:$H$7,D$17)-INDEX('LBO Model'!$D$37:$H$37,D$17)+INDEX('LBO Model'!$D$38:$H$38,D$17))/Transaction!$B$8)^(1/D$17)-1 -> 0.12719644
A22: 10 | B22: =(($A22*INDEX('LBO Model'!$D$7:$H$7,B$17)-INDEX('LBO Model'!$D$37:$H$37,B$17)+INDEX('LBO Model'!$D$38:$H$38,B$17))/Transaction!$B$8)^(1/B$17)-1 -> 0.13404028 | C22: =(($A22*INDEX('LBO Model'!$D$7:$H$7,C$17)-INDEX('LBO Model'!$D$37:$H$37,C$17)+INDEX('LBO Model'!$D$38:$H$38,C$17))/Transaction!$B$8)^(1/C$17)-1 -> 0.13919197 | D22: =(($A22*INDEX('LBO Model'!$D$7:$H$7,D$17)-INDEX('LBO Model'!$D$37:$H$37,D$17)+INDEX('LBO Model'!$D$38:$H$38,D$17))/Transaction!$B$8)^(1/D$17)-1 -> 0.13931823
A23: 10.5 | B23: =(($A23*INDEX('LBO Model'!$D$7:$H$7,B$17)-INDEX('LBO Model'!$D$37:$H$37,B$17)+INDEX('LBO Model'!$D$38:$H$38,B$17))/Transaction!$B$8)^(1/B$17)-1 -> 0.15570173 | C23: =(($A23*INDEX('LBO Model'!$D$7:$H$7,C$17)-INDEX('LBO Model'!$D$37:$H$37,C$17)+INDEX('LBO Model'!$D$38:$H$38,C$17))/Transaction!$B$8)^(1/C$17)-1 -> 0.15455623 | D23: =(($A23*INDEX('LBO Model'!$D$7:$H$7,D$17)-INDEX('LBO Model'!$D$37:$H$37,D$17)+INDEX('LBO Model'!$D$38:$H$38,D$17))/Transaction!$B$8)^(1/D$17)-1 -> 0.15094507
A24: 11 | B24: =(($A24*INDEX('LBO Model'!$D$7:$H$7,B$17)-INDEX('LBO Model'!$D$37:$H$37,B$17)+INDEX('LBO Model'!$D$38:$H$38,B$17))/Transaction!$B$8)^(1/B$17)-1 -> 0.17658026 | C24: =(($A24*INDEX('LBO Model'!$D$7:$H$7,C$17)-INDEX('LBO Model'!$D$37:$H$37,C$17)+INDEX('LBO Model'!$D$38:$H$38,C$17))/Transaction!$B$8)^(1/C$17)-1 -> 0.1693305 | D24: =(($A24*INDEX('LBO Model'!$D$7:$H$7,D$17)-INDEX('LBO Model'!$D$37:$H$37,D$17)+INDEX('LBO Model'!$D$38:$H$38,D$17))/Transaction!$B$8)^(1/D$17)-1 -> 0.16212023
A25: 11.5 | B25: =(($A25*INDEX('LBO Model'!$D$7:$H$7,B$17)-INDEX('LBO Model'!$D$37:$H$37,B$17)+INDEX('LBO Model'!$D$38:$H$38,B$17))/Transaction!$B$8)^(1/B$17)-1 -> 0.19674299 | C25: =(($A25*INDEX('LBO Model'!$D$7:$H$7,C$17)-INDEX('LBO Model'!$D$37:$H$37,C$17)+INDEX('LBO Model'!$D$38:$H$38,C$17))/Transaction!$B$8)^(1/C$17)-1 -> 0.18356507 | D25: =(($A25*INDEX('LBO Model'!$D$7:$H$7,D$17)-INDEX('LBO Model'!$D$37:$H$37,D$17)+INDEX('LBO Model'!$D$38:$H$38,D$17))/Transaction!$B$8)^(1/D$17)-1 -> 0.17288138
A26: 12 | B26: =(($A26*INDEX('LBO Model'!$D$7:$H$7,B$17)-INDEX('LBO Model'!$D$37:$H$37,B$17)+INDEX('LBO Model'!$D$38:$H$38,B$17))/Transaction!$B$8)^(1/B$17)-1 -> 0.21624828 | C26: =(($A26*INDEX('LBO Model'!$D$7:$H$7,C$17)-INDEX('LBO Model'!$D$37:$H$37,C$17)+INDEX('LBO Model'!$D$38:$H$38,C$17))/Transaction!$B$8)^(1/C$17)-1 -> 0.19730383 | D26: =(($A26*INDEX('LBO Model'!$D$7:$H$7,D$17)-INDEX('LBO Model'!$D$37:$H$37,D$17)+INDEX('LBO Model'!$D$38:$H$38,D$17))/Transaction!$B$8)^(1/D$17)-1 -> 0.1832615
A28: Sensitivity 2: FY2032E (5-yr) IRR vs. offer premium and exit multiple
A29: Offer premium \ Exit multiple | B29: 9 | C29: 9.5 | D29: 10 | E29: 10.5 | F29: 11
A30: 0.1 | B30: =((B$29*'LBO Model'!$H$7-'LBO Model'!$H$37+'LBO Model'!$H$38)/((Assumptions!$B$5*(1+$A30)*Assumptions!$B$8)+Assumptions!$B$10+Transaction!$B$14+Assumptions!$B$34*((Assumptions!$B$5*(1+$A30)*Assumptions!$B$8)+Assumptions!$B$10-Assumptions!$B$11)-Transaction!$B$5-Transaction!$B$6-Transaction!$B$7))^(1/5)-1 -> 0.1757795 | C30: =((C$29*'LBO Model'!$H$7-'LBO Model'!$H$37+'LBO Model'!$H$38)/((Assumptions!$B$5*(1+$A30)*Assumptions!$B$8)+Assumptions!$B$10+Transaction!$B$14+Assumptions!$B$34*((Assumptions!$B$5*(1+$A30)*Assumptions!$B$8)+Assumptions!$B$10-Assumptions!$B$11)-Transaction!$B$5-Transaction!$B$6-Transaction!$B$7))^(1/5)-1 -> 0.18914245 | D30: =((D$29*'LBO Model'!$H$7-'LBO Model'!$H$37+'LBO Model'!$H$38)/((Assumptions!$B$5*(1+$A30)*Assumptions!$B$8)+Assumptions!$B$10+Transaction!$B$14+Assumptions!$B$34*((Assumptions!$B$5*(1+$A30)*Assumptions!$B$8)+Assumptions!$B$10-Assumptions!$B$11)-Transaction!$B$5-Transaction!$B$6-Transaction!$B$7))^(1/5)-1 -> 0.2019304 | E30: =((E$29*'LBO Model'!$H$7-'LBO Model'!$H$37+'LBO Model'!$H$38)/((Assumptions!$B$5*(1+$A30)*Assumptions!$B$8)+Assumptions!$B$10+Transaction!$B$14+Assumptions!$B$34*((Assumptions!$B$5*(1+$A30)*Assumptions!$B$8)+Assumptions!$B$10-Assumptions!$B$11)-Transaction!$B$5-Transaction!$B$6-Transaction!$B$7))^(1/5)-1 -> 0.2141962 | F30: =((F$29*'LBO Model'!$H$7-'LBO Model'!$H$37+'LBO Model'!$H$38)/((Assumptions!$B$5*(1+$A30)*Assumptions!$B$8)+Assumptions!$B$10+Transaction!$B$14+Assumptions!$B$34*((Assumptions!$B$5*(1+$A30)*Assumptions!$B$8)+Assumptions!$B$10-Assumptions!$B$11)-Transaction!$B$5-Transaction!$B$6-Transaction!$B$7))^(1/5)-1 -> 0.2259855
A31: 0.2 | B31: =((B$29*'LBO Model'!$H$7-'LBO Model'!$H$37+'LBO Model'!$H$38)/((Assumptions!$B$5*(1+$A31)*Assumptions!$B$8)+Assumptions!$B$10+Transaction!$B$14+Assumptions!$B$34*((Assumptions!$B$5*(1+$A31)*Assumptions!$B$8)+Assumptions!$B$10-Assumptions!$B$11)-Transaction!$B$5-Transaction!$B$6-Transaction!$B$7))^(1/5)-1 -> 0.14270512 | C31: =((C$29*'LBO Model'!$H$7-'LBO Model'!$H$37+'LBO Model'!$H$38)/((Assumptions!$B$5*(1+$A31)*Assumptions!$B$8)+Assumptions!$B$10+Transaction!$B$14+Assumptions!$B$34*((Assumptions!$B$5*(1+$A31)*Assumptions!$B$8)+Assumptions!$B$10-Assumptions!$B$11)-Transaction!$B$5-Transaction!$B$6-Transaction!$B$7))^(1/5)-1 -> 0.15569217 | D31: =((D$29*'LBO Model'!$H$7-'LBO Model'!$H$37+'LBO Model'!$H$38)/((Assumptions!$B$5*(1+$A31)*Assumptions!$B$8)+Assumptions!$B$10+Transaction!$B$14+Assumptions!$B$34*((Assumptions!$B$5*(1+$A31)*Assumptions!$B$8)+Assumptions!$B$10-Assumptions!$B$11)-Transaction!$B$5-Transaction!$B$6-Transaction!$B$7))^(1/5)-1 -> 0.1681204 | E31: =((E$29*'LBO Model'!$H$7-'LBO Model'!$H$37+'LBO Model'!$H$38)/((Assumptions!$B$5*(1+$A31)*Assumptions!$B$8)+Assumptions!$B$10+Transaction!$B$14+Assumptions!$B$34*((Assumptions!$B$5*(1+$A31)*Assumptions!$B$8)+Assumptions!$B$10-Assumptions!$B$11)-Transaction!$B$5-Transaction!$B$6-Transaction!$B$7))^(1/5)-1 -> 0.18004117 | F31: =((F$29*'LBO Model'!$H$7-'LBO Model'!$H$37+'LBO Model'!$H$38)/((Assumptions!$B$5*(1+$A31)*Assumptions!$B$8)+Assumptions!$B$10+Transaction!$B$14+Assumptions!$B$34*((Assumptions!$B$5*(1+$A31)*Assumptions!$B$8)+Assumptions!$B$10-Assumptions!$B$11)-Transaction!$B$5-Transaction!$B$6-Transaction!$B$7))^(1/5)-1 -> 0.19149884
A32: 0.3 | B32: =((B$29*'LBO Model'!$H$7-'LBO Model'!$H$37+'LBO Model'!$H$38)/((Assumptions!$B$5*(1+$A32)*Assumptions!$B$8)+Assumptions!$B$10+Transaction!$B$14+Assumptions!$B$34*((Assumptions!$B$5*(1+$A32)*Assumptions!$B$8)+Assumptions!$B$10-Assumptions!$B$11)-Transaction!$B$5-Transaction!$B$6-Transaction!$B$7))^(1/5)-1 -> 0.11452961 | C32: =((C$29*'LBO Model'!$H$7-'LBO Model'!$H$37+'LBO Model'!$H$38)/((Assumptions!$B$5*(1+$A32)*Assumptions!$B$8)+Assumptions!$B$10+Transaction!$B$14+Assumptions!$B$34*((Assumptions!$B$5*(1+$A32)*Assumptions!$B$8)+Assumptions!$B$10-Assumptions!$B$11)-Transaction!$B$5-Transaction!$B$6-Transaction!$B$7))^(1/5)-1 -> 0.12719644 | D32: =((D$29*'LBO Model'!$H$7-'LBO Model'!$H$37+'LBO Model'!$H$38)/((Assumptions!$B$5*(1+$A32)*Assumptions!$B$8)+Assumptions!$B$10+Transaction!$B$14+Assumptions!$B$34*((Assumptions!$B$5*(1+$A32)*Assumptions!$B$8)+Assumptions!$B$10-Assumptions!$B$11)-Transaction!$B$5-Transaction!$B$6-Transaction!$B$7))^(1/5)-1 -> 0.13931823 | E32: =((E$29*'LBO Model'!$H$7-'LBO Model'!$H$37+'LBO Model'!$H$38)/((Assumptions!$B$5*(1+$A32)*Assumptions!$B$8)+Assumptions!$B$10+Transaction!$B$14+Assumptions!$B$34*((Assumptions!$B$5*(1+$A32)*Assumptions!$B$8)+Assumptions!$B$10-Assumptions!$B$11)-Transaction!$B$5-Transaction!$B$6-Transaction!$B$7))^(1/5)-1 -> 0.15094507 | F32: =((F$29*'LBO Model'!$H$7-'LBO Model'!$H$37+'LBO Model'!$H$38)/((Assumptions!$B$5*(1+$A32)*Assumptions!$B$8)+Assumptions!$B$10+Transaction!$B$14+Assumptions!$B$34*((Assumptions!$B$5*(1+$A32)*Assumptions!$B$8)+Assumptions!$B$10-Assumptions!$B$11)-Transaction!$B$5-Transaction!$B$6-Transaction!$B$7))^(1/5)-1 -> 0.16212023
A33: 0.4 | B33: =((B$29*'LBO Model'!$H$7-'LBO Model'!$H$37+'LBO Model'!$H$38)/((Assumptions!$B$5*(1+$A33)*Assumptions!$B$8)+Assumptions!$B$10+Transaction!$B$14+Assumptions!$B$34*((Assumptions!$B$5*(1+$A33)*Assumptions!$B$8)+Assumptions!$B$10-Assumptions!$B$11)-Transaction!$B$5-Transaction!$B$6-Transaction!$B$7))^(1/5)-1 -> 0.090067912 | C33: =((C$29*'LBO Model'!$H$7-'LBO Model'!$H$37+'LBO Model'!$H$38)/((Assumptions!$B$5*(1+$A33)*Assumptions!$B$8)+Assumptions!$B$10+Transaction!$B$14+Assumptions!$B$34*((Assumptions!$B$5*(1+$A33)*Assumptions!$B$8)+Assumptions!$B$10-Assumptions!$B$11)-Transaction!$B$5-Transaction!$B$6-Transaction!$B$7))^(1/5)-1 -> 0.10245673 | D33: =((D$29*'LBO Model'!$H$7-'LBO Model'!$H$37+'LBO Model'!$H$38)/((Assumptions!$B$5*(1+$A33)*Assumptions!$B$8)+Assumptions!$B$10+Transaction!$B$14+Assumptions!$B$34*((Assumptions!$B$5*(1+$A33)*Assumptions!$B$8)+Assumptions!$B$10-Assumptions!$B$11)-Transaction!$B$5-Transaction!$B$6-Transaction!$B$7))^(1/5)-1 -> 0.11431247 | E33: =((E$29*'LBO Model'!$H$7-'LBO Model'!$H$37+'LBO Model'!$H$38)/((Assumptions!$B$5*(1+$A33)*Assumptions!$B$8)+Assumptions!$B$10+Transaction!$B$14+Assumptions!$B$34*((Assumptions!$B$5*(1+$A33)*Assumptions!$B$8)+Assumptions!$B$10-Assumptions!$B$11)-Transaction!$B$5-Transaction!$B$6-Transaction!$B$7))^(1/5)-1 -> 0.12568412 | F33: =((F$29*'LBO Model'!$H$7-'LBO Model'!$H$37+'LBO Model'!$H$38)/((Assumptions!$B$5*(1+$A33)*Assumptions!$B$8)+Assumptions!$B$10+Transaction!$B$14+Assumptions!$B$34*((Assumptions!$B$5*(1+$A33)*Assumptions!$B$8)+Assumptions!$B$10-Assumptions!$B$11)-Transaction!$B$5-Transaction!$B$6-Transaction!$B$7))^(1/5)-1 -> 0.13661401
A34: 0.5 | B34: =((B$29*'LBO Model'!$H$7-'LBO Model'!$H$37+'LBO Model'!$H$38)/((Assumptions!$B$5*(1+$A34)*Assumptions!$B$8)+Assumptions!$B$10+Transaction!$B$14+Assumptions!$B$34*((Assumptions!$B$5*(1+$A34)*Assumptions!$B$8)+Assumptions!$B$10-Assumptions!$B$11)-Transaction!$B$5-Transaction!$B$6-Transaction!$B$7))^(1/5)-1 -> 0.068510864 | C34: =((C$29*'LBO Model'!$H$7-'LBO Model'!$H$37+'LBO Model'!$H$38)/((Assumptions!$B$5*(1+$A34)*Assumptions!$B$8)+Assumptions!$B$10+Transaction!$B$14+Assumptions!$B$34*((Assumptions!$B$5*(1+$A34)*Assumptions!$B$8)+Assumptions!$B$10-Assumptions!$B$11)-Transaction!$B$5-Transaction!$B$6-Transaction!$B$7))^(1/5)-1 -> 0.080654679 | D34: =((D$29*'LBO Model'!$H$7-'LBO Model'!$H$37+'LBO Model'!$H$38)/((Assumptions!$B$5*(1+$A34)*Assumptions!$B$8)+Assumptions!$B$10+Transaction!$B$14+Assumptions!$B$34*((Assumptions!$B$5*(1+$A34)*Assumptions!$B$8)+Assumptions!$B$10-Assumptions!$B$11)-Transaction!$B$5-Transaction!$B$6-Transaction!$B$7))^(1/5)-1 -> 0.092275962 | E34: =((E$29*'LBO Model'!$H$7-'LBO Model'!$H$37+'LBO Model'!$H$38)/((Assumptions!$B$5*(1+$A34)*Assumptions!$B$8)+Assumptions!$B$10+Transaction!$B$14+Assumptions!$B$34*((Assumptions!$B$5*(1+$A34)*Assumptions!$B$8)+Assumptions!$B$10-Assumptions!$B$11)-Transaction!$B$5-Transaction!$B$6-Transaction!$B$7))^(1/5)-1 -> 0.10342273 | F34: =((F$29*'LBO Model'!$H$7-'LBO Model'!$H$37+'LBO Model'!$H$38)/((Assumptions!$B$5*(1+$A34)*Assumptions!$B$8)+Assumptions!$B$10+Transaction!$B$14+Assumptions!$B$34*((Assumptions!$B$5*(1+$A34)*Assumptions!$B$8)+Assumptions!$B$10-Assumptions!$B$11)-Transaction!$B$5-Transaction!$B$6-Transaction!$B$7))^(1/5)-1 -> 0.11413647
A36: Ability-to-pay: what could a sponsor pay and still earn the hurdle IRR?
A37: Target IRR (hurdle) | B37: =Assumptions!$B$62 -> 0.2
A38: Exit equity value (FY2032E, base exit multiple) | B38: =D11 -> 8632.7111
A39: Maximum sponsor equity cheque | B39: =B38/(1+B37)^5 -> 3469.293
A40: Maximum equity purchase price | B40: =(B39-Assumptions!$B$10-Transaction!B14-Assumptions!$B$34*(Assumptions!$B$10-Assumptions!$B$11)+Transaction!B5+Transaction!B6+Transaction!B7)/(1+Assumptions!$B$34) -> 5746.6451
A41: Maximum offer price per share (Rs) | B41: =B40/Assumptions!$B$8 -> 1163.2885
A42: Implied premium / (discount) to current price | B42: =B41/Assumptions!$B$5-1 -> 0.10526221
A43: Implied EV / FY2027E Adj. EBITDA | B43: =(B40+Assumptions!$B$10-Assumptions!$B$11)/Assumptions!$B$14 -> 8.6921381
A45: IRR = MOIC^(1/years) - 1 because there are no interim distributions. Sensitivity 2 recomputes the sponsor equity cheque for each premium (debt is fixed at 3.5x FY2027E EBITDA, so a higher price is funded entirely with equity) while exit equity is unchanged. The ability-to-pay block solves backwards: given the exit value and the hurdle IRR, how large an equity cheque - and therefore how high an offer price - is affordable.
